Workbook

Sheet Resumo
B2: RESUMO DE TRABALHO DOS COMPRESSORES
B7: N° | C7: Compressor | D7: Ultima Preventiva | E7: Hrs carga Preventiva | F7: Hrs carga Atual | G7: Hr semanal | H7: Diferença das Hrs | I7: Próxima Preventiva | J7: Ordem de Serviço
B8: 1 | C8: SCHULZ | D8: =IF(SUM(Preventivas!D7:D26)="","",MAX(Preventivas!D7:D26)) -> 44974 | E8: =MAX(Preventivas!M7:M26) -> 25752 | F8: =MAX('Hrs de carga'!$C$10:$C$102) -> 25668 | G8: =Tabela436[[#This Row],[Hrs carga Atual]]-(LARGE(Tabela62[SCHULZ],2)) -> 0 | H8: =Resumo!$F8-Resumo!$E8 -> -84 | I8: =4000-Resumo!$H8 -> 4084 | J8: Inativo
B9: 2 | C9: N°2 GA-55 VSD | D9: =IF(SUM(Preventivas!E7:E26)="","",MAX(Preventivas!E7:E26)) -> 46261 | E9: =MAX(Preventivas!N7:N26) -> 65105 | F9: =MAX('Hrs de carga'!$D$10:$D$102) -> 65994 | G9: =Tabela436[[#This Row],[Hrs carga Atual]]-(LARGE(Tabela62[GA-55 VSD],2)) -> 159 | H9: =Resumo!$F9-Resumo!$E9 -> 889 | I9: =4000-Resumo!$H9 -> 3111 | J9: 2994
B10: 3 | C10: N°3 GA-55 FF | D10: =IF(SUM(Preventivas!F7:F26)="","",MAX(Preventivas!F7:F26)) -> 46261 | E10: =MAX(Preventivas!O7:O26) -> 45369 | F10: =MAX('Hrs de carga'!$E$10:$E$102) -> 45434 | G10: =Tabela436[[#This Row],[Hrs carga Atual]]-(LARGE(Tabela62[GA-55 FF],2)) -> 15 | H10: =Resumo!$F10-Resumo!$E10 -> 65 | I10: =4000-Resumo!$H10 -> 3935 | J10: 2696
B11: 4 | C11: N°4 GA-45 | D11: =IF(SUM(Preventivas!G7:G26)="","",MAX(Preventivas!G7:G26)) -> 46146 | E11: =MAX(Preventivas!P7:P26) -> 27429 | F11: =MAX('Hrs de carga'!$F$10:$F$102) -> 30665 | G11: =Tabela436[[#This Row],[Hrs carga Atual]]-(LARGE(Tabela62[GA-45 ],2)) -> 0 | H11: =Resumo!$F11-Resumo!$E11 -> 3236 | I11: =4000-Resumo!$H11 -> 764 | J11: 2787
B12: 5 | C12: N°5 GA-55 VSD FF5 | D12: =IF(SUM(Preventivas!H7:H26)="","",MAX(Preventivas!H7:H26)) -> 46225 | E12: =MAX(Preventivas!Q7:Q26) -> 25644 | F12: =MAX('Hrs de carga'!$G$10:$G$102) -> 27134 | G12: =Tabela436[[#This Row],[Hrs carga Atual]]-(LARGE(Tabela62[GA-55 VSDFF],2)) -> 0 | H12: =Resumo!$F12-Resumo!$E12 -> 1490 | I12: =4000-Resumo!$H12 -> 2510 | J12: 2914
B13: 6 | C13: Nº6 GA-55 VSD FF6 | D13: =IF(SUM(Preventivas!I7:I26)="","",MAX(Preventivas!I7:I26)) -> 46260 | E13: =MAX(Preventivas!R7:R26) -> 26217 | F13: =MAX('Hrs de carga'!$H$10:$H$102) -> 27227 | G13: =Tabela436[[#This Row],[Hrs carga Atual]]-(LARGE(Tabela62[GA-55 VSDFF2],2)) -> 169 | H13: =Resumo!$F13-Resumo!$E13 -> 1010 | I13: =4000-Resumo!$H13 -> 2990 | J13: 2993
B14: 1 | C14: N°7 GA-55 VSD FF7 | D14: =IF(SUM(Preventivas!J7:J26)="","",MAX(Preventivas!J7:J26)) -> 46261 | E14: =MAX(Preventivas!S7:S26) -> 13111 | F14: =MAX('Hrs de carga'!$I$10:$I$102) -> 14008 | G14: =Tabela436[[#This Row],[Hrs carga Atual]]-(LARGE(Tabela62[GA-55 VSDFF3],2)) -> 88 | H14: =Resumo!$F14-Resumo!$E14 -> 897 | I14: =4000-Resumo!$H14 -> 3103 | J14: 2995

Sheet Hrs de carga
B3: Horímetro - Horas de Carga de Trabalho
B8: Compressor | C8: 1 | D8: 2 | E8: 3 | F8: 4 | G8: 5 | H8: 6 | I8: 7
B9: Data | C9: SCHULZ | D9: GA-55 VSD | E9: GA-55 FF | F9: GA-45 | G9: GA-55 VSDFF | H9: GA-55 VSDFF2 | I9: GA-55 VSDFF3
B10: 44935 | C10: 25646 | D10: 37441 | E10: 31751 | F10: 18788 | G10: 1256 | H10: 1270
B11: 44943 | C11: 25646 | D11: 37442 | E11: 31770 | F11: 18789 | G11: 1414 | H11: 1419
B12: 44949 | C12: 25646 | D12: 37446 | E12: 31773 | F12: 18792 | G12: 1530 | H12: 1536
B13: 44957 | C13: 25646 | D13: 37449 | E13: 31775 | F13: 18792 | G13: 1694 | H13: 1698
B14: 44966 | C14: 25646 | D14: 37452 | E14: 31779 | F14: 18793 | G14: 1863 | H14: 1669
B15: 44970 | C15: 25646 | D15: 37453 | E15: 31780 | F15: 18798 | G15: 1916 | H15: 1922
B16: 44980 | C16: 25668 | D16: 37453 | E16: 31780 | F16: 18798 | G16: 1916 | H16: 1922
B17: 44985 | C17: 25668 | D17: 37464 | E17: 31801 | F17: 18814 | G17: 2248 | H17: 2255
B18: 44991 | C18: 25668 | D18: 37465 | E18: 31803 | F18: 18826 | G18: 2363 | H18: 2374
B19: 45001 | C19: 25668 | D19: 37468 | E19: 31820 | F19: 18844 | G19: 2583 | H19: 2557
B20: 45007 | C20: 25668 | D20: 37470 | E20: 31824 | F20: 18844 | G20: 2684 | H20: 2656
B21: 45014 | C21: 25668 | D21: 37470 | E21: 31826 | F21: 18844 | G21: 2807 | H21: 2787
B22: 45030 | C22: 25668 | D22: 37481 | E22: 31857 | F22: 18845 | G22: 3045 | H22: 3047
B23: 45041 | C23: 25668 | D23: 37481 | E23: 31869 | F23: 18845 | G23: 3254 | H23: 3263
B24: 45061 | C24: 25668 | D24: 37490 | E24: 31923 | F24: 18848 | G24: 3611 | H24: 3621
B25: 45075 | C25: 25668 | D25: 37494 | E25: 31950 | F25: 18878 | G25: 3911 | H25: 3953
B26: 45089 | C26: 25668 | D26: 37495 | E26: 31962 | F26: 18878 | G26: 4200 | H26: 4241
B27: 45103 | C27: 25668 | D27: 37498 | E27: 32017 | F27: 18879 | G27: 4484 | H27: 4532
B28: 45114 | C28: 25668 | D28: 37499 | E28: 32025 | F28: 18879 | G28: 4734 | H28: 4782
B29: 45120 | C29: 25668 | D29: 37502 | E29: 32025 | F29: 18879 | G29: 4871 | H29: 4883
B30: 45131 | C30: 25668 | D30: 37504 | E30: 32033 | F30: 18879 | G30: 5112 | H30: 5121
B31: 45138 | C31: 25668 | D31: 37508 | E31: 32054 | F31: 18881 | G31: 5277 | H31: 5286
B32: 45145 | C32: 25668 | D32: 37509 | E32: 32084 | F32: 18887 | G32: 5443 | H32: 5452
B33: 45160 | C33: 25668 | D33: 37510 | E33: 32123 | F33: 18902 | G33: 5757 | H33: 5796
B34: 45166 | C34: 25668 | D34: 37510 | E34: 32134 | F34: 18909 | G34: 5901 | H34: 5939
B35: 45180 | C35: 25668 | D35: 37510 | E35: 32135 | F35: 18942 | G35: 6235 | H35: 6214
B36: 45187 | C36: 25668 | D36: 37511 | E36: 32139 | F36: 18974 | G36: 6375 | H36: 6355
B37: 45202 | C37: 25668 | D37: 37512 | E37: 32143 | F37: 18985 | G37: 6700 | H37: 6676
B38: 45208 | C38: 25668 | D38: 37512 | E38: 32147 | F38: 18989 | G38: 6863 | H38: 6840
B39: 45206 | C39: 25668 | D39: 37549 | E39: 32193 | F39: 19003 | G39: 7458 | H39: 7433
B40: 45244 | C40: 25668 | D40: 37594 | E40: 32208 | F40: 19013 | G40: 7625 | H40: 7600
B41: 45251 | C41: 25668 | D41: 37603 | E41: 32232 | F41: 19022 | G41: 7789 | H41: 7757
B42: 45258 | C42: 25668 | D42: 37606 | E42: 32254 | F42: 19026 | G42: 7929 | H42: 7906
B43: 45267 | C43: 25668 | D43: 37620 | E43: 32286 | F43: 19032 | G43: 8134 | H43: 8111
B44: 45271 | C44: 25668 | D44: 37620 | E44: 32305 | F44: 19032 | G44: 8229 | H44: 8205
B45: 45306 | C45: 25668 | D45: 37621 | E45: 32357 | F45: 19036 | G45: 8572 | H45: 8609
B46: 45314 | C46: 25668 | D46: 37625 | E46: 32387 | F46: 19048 | G46: 8821 | H46: 8853
...

Sheet Preventivas
C3: Manutenções Preventivas | L3: Horas da Manutenções Preventivas
C5: Compressor | D5: 1 | E5: 2 | F5: 3 | G5: 4 | H5: 5 | I5: 6 | J5: 7 | L5: Compressor | M5: 1 | N5: 2 | O5: 3 | P5: 4 | Q5: 5 | R5: 6 | S5: 7
C6: Hrs de carga | D6: SCHULZ | E6: GA-55 VSD | F6: GA-55 FF | G6: GA-45 | H6: GA-55 VSDFF | I6: GA-55 VSDFF | J6: GA-55 VSDFF | L6: Hrs de carga | M6: SCHULZ | N6: GA-55 VSD | O6: GA-55 FF | P6: GA-45 | Q6: GA-55 VSDFF | R6: GA-55 VSDFF | S6: GA-55 VSDFF
B7: 24 mil | C7: 8 mil horas | D7: 44356 | E7: 43991 | F7: 44235 | G7: 44356 | L7: 8 mil horas | M7: 20949 | O7: 28602 | P7: 15499
C8: 2 mil horas | D8: - | E8: 44214 | J8: 24/01//2025 | L8: 2 mil horas | N8: 35015 | S8: 1919
C9: 4 mil horas | E9: 44764 | G9: 44764 | H9: 45056 | I9: 45056 | J9: 46261 | L9: 4 mil horas | N9: 55524 | P9: 24204 | Q9: 3520 | R9: 3520 | S9: 13111
C10: 6 mil horas | H10: 45159 | I10: 45159 | L10: 6 mil horas | Q10: 5774 | R10: 5737
C11: 8 mil horas | F11: 44764 | H11: 45261 | I11: 45261 | L11: 8 mil horas | O11: 38813 | Q11: 7997 | R11: 8019
C12: 2 mil horas | L12: 2 mil horas
C13: 4 mil horas | F13: 44973 | H13: 45490 | I13: 45490 | L13: 4 mil horas | O13: 40288 | Q13: 12005 | R13: 12095
B14: 16 mil | C14: 8 mil horas | D14: 44974 | E14: 44973 | G14: 44973 | H14: 45673 | I14: 45673 | L14: 8 mil horas | M14: 25752 | N14: 57192 | P14: 25339 | Q14: 16056 | R14: 16031
C15: 2 mil horas | L15: 2 mil horas
C16: 4 mil horas | E16: 45491 | F16: 45492 | G16: 45492 | L16: 4 mil horas | N16: 58840 | O16: 43071 | P16: 27095
B17: 24 mil | C17: 8 mil horas | E17: 45743 | F17: 45743 | G17: 46146 | H17: 46225 | I17: 46260 | L17: 8 mil horas | N17: 60542 | O17: 43686 | P17: 27429 | Q17: 25644 | R17: 26217
C18: 2 mil horas | F18: 46261 | L18: 2 mil horas | O18: 45369
C19: 4 mil horas | E19: 46261 | L19: 4 mil horas | N19: 65105
C20: 8 mil horas | L20: 8 mil horas
C21: 2 mil horas | L21: 2 mil horas
C22: 4 mil horas | L22: 4 mil horas
B23: 16 mil | C23: 8 mil horas | L23: 8 mil horas
C24: 2 mil horas | L24: 2 mil horas
C25: 4 mil horas | L25: 4 mil horas
B26: 24 mil | C26: 8 mil horas | L26: 8 mil horas
D84: 1

Sheet Base
C3: 44935 | D3: 44943 | E3: 44949 | F3: 44957 | G3: 44966 | H3: 44970 | I3: 44980 | J3: 44985 | K3: 44991 | L3: 45001 | M3: 45007 | N3: 45014 | O3: 45029 | P3: 45041 | Q3: 45061 | R3: 45075 | S3: 45089 | T3: 45103 | U3: 45114 | V3: 45120 | W3: 45131 | X3: 45138 | Y3: 45145 | Z3: 45160 | AA3: 45166 | AB3: 45180 | AC3: 45187 | AD3: 45201 | AE3: 45208 | AF3: 45237 | AG3: 45244 | AH3: 45251 | AI3: 45258 | AJ3: 45267 | AK3: 45637 | AL3: 45306 | AM3: 45314 | AN3: 45334 | AO3: 45342 | AP3: 45369 | AQ3: 45392 | AR3: 45412 | AT3: 45552 | AU3: 45561 | AV3: 45565 | AW3: 45582 | AX3: 45593 | AY3: 45610 | BB3: 45665 | BC3: 45671 | BE3: 45726 | BF3: 45779 | BG3: 45790 | BH3: 45790 | BI3: 46282 | BJ3: 46290 | BK3: 46295 | BL3: 46302
B5: SCHLUZ | C5: SCHULZ Nº01 | D5: SCHULZ Nº01 | E5: SCHULZ Nº01 | F5: SCHULZ Nº01 | G5: SCHULZ Nº01 | H5: SCHULZ Nº01 | I5: SCHULZ Nº01 | J5: SCHULZ Nº01 | K5: SCHULZ Nº01 | L5: SCHULZ Nº01 | M5: SCHULZ Nº01 | N5: SCHULZ Nº01 | O5: SCHULZ Nº01 | P5: SCHULZ Nº01 | Q5: SCHULZ Nº01 | R5: SCHULZ Nº01 | S5: SCHULZ Nº01 | T5: SCHULZ Nº01 | U5: SCHULZ Nº01 | V5: SCHULZ Nº01 | W5: SCHULZ Nº01 | X5: SCHULZ Nº01 | Y5: SCHULZ Nº01 | Z5: SCHULZ Nº01 | AA5: SCHULZ Nº01 | AB5: SCHULZ Nº01 | AC5: SCHULZ Nº01 | AD5: SCHULZ Nº01 | AE5: SCHULZ Nº01 | AF5: SCHULZ Nº01 | AG5: SCHULZ Nº01 | AH5: SCHULZ Nº01 | AI5: SCHULZ Nº01 | AJ5: SCHULZ Nº01 | AK5: SCHULZ Nº01 | AL5: SCHULZ Nº01 | AM5: SCHULZ Nº01 | AN5: SCHULZ Nº01 | AO5: SCHULZ Nº01 | AP5: SCHULZ Nº01 | AQ5: SCHULZ Nº01 | AR5: SCHULZ Nº01 | AS5: SCHULZ Nº01 | AT5: SCHULZ Nº01 | AU5: SCHULZ Nº01 | AV5: SCHULZ Nº01 | AW5: SCHULZ Nº01 | AX5: Nº01 | AY5: Nº01 | AZ5: Nº01 | BA5: Nº01 | BB5: Nº01 | BC5: Nº01 | BD5: Nº01 | BE5: SCHULZ desativado. | BF5: SCHULZ desativado. | BG5: SCHULZ desativado. | BH5: SCHULZ desativado. | BI5: SCHULZ desativado. | BJ5: SCHULZ desativado. | BL5: SCHULZ desativado.
C6: 25731 H. Trabalho | D6: 25731 H. Trabalho | E6: 25731 H. Trabalho | F6: 25731 H. Trabalho | G6: 25731 H. Trabalho | H6: 25731 H. Trabalho | I6: 25753 H. Trabalho | J6: 25753 H. Trabalho | K6: 25753 H. Trabalho | L6: 25753 H. Trabalho | M6: 25753 H. Trabalho | N6: 25753 H. Trabalho | O6: 25753 H. Trabalho | P6: 25753 H. Trabalho | Q6: PARADO | R6: 25753 H. Trabalho | S6: 25753 H. Trabalho | T6: 25753 H. Trabalho | U6: 25753 H. Trabalho | V6: 25753 H. Trabalho | W6: 25753 H. Trabalho | X6: 25753 H. Trabalho | Y6: 25753 H. Trabalho | Z6: 25753 H. Trabalho | AA6: 25753 H. Trabalho | AB6: 25753 H. Trabalho | AC6: 25753 H. Trabalho | AD6: 25753 H. Trabalho | AE6: 25753 H. Trabalho | AF6: 25753 H. Trabalho | AG6: 25753 H. Trabalho | AH6: 25753 H. Trabalho | AI6: 25753 H. Trabalho | AJ6: 25753 H. Trabalho | AK6: 25753 H. Trabalho | AL6: 25753 H. Trabalho | AM6: 25753 H. Trabalho | AN6: 25753 H. Trabalho | AO6: 25753 H. Trabalho | AP6: 25753 H. Trabalho | AQ6: 25753 H. Trabalho | AR6: 25753 H. Trabalho | AS6: 25753 H. Trabalho | AT6: 25753 H. Trabalho | AU6: 25753 H. Trabalho | AV6: 25753 H. Trabalho | AW6: 25753 H. Trabalho | AX6: 493 H. funcionamento. | AY6: 832 H. funcionamento. | AZ6: 1047 H. funcionamento. | BA6: 1166 H. funcionamento. | BB6: 1561 H. funcionamento. | BC6: 1704 H. funcionamento. | BD6: 2265H. funcionamento. | BE6: Nº01 | BF6: Nº01 | BG6: Nº01 | BH6: Nº01 | BI6: GA55VDS N°07 | BJ6: GA55VDS N°07 | BK6: GA55VDS N°07 | BL6: GA55VDS N°07
C7: 25646 H. Carga | D7: 25646 H. Carga | E7: 25646 H. Carga | F7: 25646 H. Carga | G7: 25646 H. Carga | H7: 25646 H. Carga | I7: 25668 H. Carga | J7: 25668 H. Carga | K7: 25668 H. Carga | L7: 25668 H. Carga | M7: 25668 H. Carga | N7: 25668 H. Carga | O7: 25668 H. Carga | P7: 25668 H. Carga COMPRESSOR SE ENCONTRA DESLIGADO | R7: 25668 H. Carga COMPRESSOR SE ENCONTRA DESLIGADO | S7: 25668 H. Carga COMPRESSOR SE ENCONTRA DESLIGADO | T7: 25668 H. Carga COMPRESSOR SE ENCONTRA DESLIGADO | U7: 25668 H. Carga COMPRESSOR SE ENCONTRA DESLIGADO | V7: 25668 H. Carga COMPRESSOR SE ENCONTRA DESLIGADO | W7: 25668 H. Carga COMPRESSOR SE ENCONTRA DESLIGADO | X7: 25668 H. Carga COMPRESSOR SE ENCONTRA DESLIGADO | Y7: 25668 H. Carga COMPRESSOR SE ENCONTRA DESLIGADO | Z7: 25668 H. Carga COMPRESSOR SE ENCONTRA DESLIGADO | AA7: 25668 H. Carga COMPRESSOR SE ENCONTRA DESLIGADO | AB7: 25668 H. Carga COMPRESSOR SE ENCONTRA DESLIGADO | AC7: 25668 H. Carga COMPRESSOR SE ENCONTRA DESLIGADO | AD7: 25668 H. Carga COMPRESSOR SE ENCONTRA DESLIGADO | AE7: 25668 H. Carga COMPRESSOR SE ENCONTRA DESLIGADO | AF7: 25668 H. Carga COMPRESSOR SE ENCONTRA DESLIGADO | AG7: 25668 H. Carga COMPRESSOR SE ENCONTRA DESLIGADO | AH7: 25668 H. Carga COMPRESSOR SE ENCONTRA DESLIGADO | AI7: 25668 H. Carga COMPRESSOR SE ENCONTRA DESLIGADO | AJ7: 25668 H. Carga COMPRESSOR SE ENCONTRA DESLIGADO | AK7: 25668 H. Carga COMPRESSOR SE ENCONTRA DESLIGADO | AL7: 25668 H. Carga COMPRESSOR SE ENCONTRA DESLIGADO | AM7: 25668 H. Carga COMPRESSOR SE ENCONTRA DESLIGADO | AN7: 25668 H. Carga COMPRESSOR SE ENCONTRA DESLIGADO | AO7: 25668 H. Carga COMPRESSOR SE ENCONTRA DESLIGADO | AP7: 25668 H. Carga COMPRESSOR SE ENCONTRA DESLIGADO | AQ7: 25668 H. Carga COMPRESSOR SE ENCONTRA DESLIGADO | AR7: 25668 H. Carga COMPRESSOR SE ENCONTRA DESLIGADO | AS7: 25668 H. Carga COMPRESSOR SE ENCONTRA DESLIGADO | AT7: 25668 H. Carga COMPRESSOR ESTA DESCONECTADO DA REDE | AU7: 25668 H. Carga COMPRESSOR ESTA DESCONECTADO DA REDE | AV7: 25668 H. Carga COMPRESSOR ESTA DESCONECTADO DA REDE | AW7: 25668 H. Carga COMPRESSOR ESTA DESCONECTADO DA REDE | BE7: 2852 H. funcionamento. | BF7: 3845 H. funcionamento. | BG7: 4066 H. funcionamento. | BH7: 4066 H. funcionamento. | BI7: 13613 H. funcionamento. | BJ7: 13799 H. funcionamento. | BK7: 13920 H. funcionamento. | BL7: 13799 H. funcionamento.
Q8: GA55 VDS Nº02
B9: GA55VSD | C9: GA55 VDS Nº02 | D9: GA55 VDS Nº02 | E9: GA55 VDS Nº02 | F9: GA55 VDS Nº02 | G9: GA55 VDS Nº02 | H9: GA55 VDS Nº02 | I9: GA55 VDS Nº02 | J9: GA55 VDS Nº02 | K9: GA55 VDS Nº02 | L9: GA55 VDS Nº02 | M9: GA55 VDS Nº02 | N9: GA55 VDS Nº02 | O9: GA55 VDS Nº02 | P9: GA55 VDS Nº02 | Q9: 57374 H. Totais | R9: GA55 VDS Nº02 | S9: GA55 VDS Nº02 | T9: GA55 VDS Nº02 | U9: GA55 VDS Nº02 | V9: GA55 VDS Nº02 | W9: GA55 VDS Nº02 | X9: GA55 VDS Nº02 | Y9: GA55 VDS Nº02 | Z9: GA55 VDS Nº02 | AA9: GA55 VDS Nº02 | AB9: GA55 VDS Nº02 | AC9: GA55 VDS Nº02 | AD9: GA55 VDS Nº02 | AE9: GA55 VDS Nº02 | AF9: GA55 VDS Nº02 | AG9: GA55 VDS Nº02 | AH9: GA55 VDS Nº02 | AI9: GA55 VDS Nº02 | AJ9: GA55 VDS Nº02 | AK9: GA55 VDS Nº02 | AL9: GA55 VDS Nº02 | AM9: GA55 VDS Nº02 | AN9: GA55 VDS Nº02 | AO9: GA55 VDS Nº02 | AP9: GA55 VDS Nº02 | AQ9: GA55 VDS Nº02 | AR9: GA55 VDS Nº02 | AS9: GA55 VDS Nº02 | AT9: GA55 VDS Nº02 | AU9: GA55 VDS Nº02 | AV9: GA55 VDS Nº02 | AW9: GA55 VDS Nº02 | AX9: GA55 VDS Nº02 | AY9: GA55 VDS Nº02 | AZ9: GA55 VDS Nº02 | BA9: GA55 VDS Nº02 | BB9: GA55 VDS Nº02 | BC9: GA55 VDS Nº02 | BD9: GA55 VDS Nº02 | BE9: GA55 VDS Nº02 | BF9: GA55 VDS Nº02 Compressor N°02 aguardando a manutenção elétrica | BG9: GA55VDS Nº02 Compressor N°02 em manutenção. | BH9: GA55VDS Nº02 Compressor N°02 em manutenção. | BI9: GA55VDS Nº02 Compressor N°02 | BJ9: GA55VDS Nº02 Compressor N°02 | BK9: GA55VDS Nº02 Compressor N°02 | BL9: GA55VDS Nº02 Compressor N°02
C10: 57117 H. Totais | D10: 57148 H. Totais | E10: 57153 H. Totais | F10: 57153 H. Totais | G10: 57168 H. Totais | H10: 57172 H. Totais | I10: 57172 H. Totais | J10: 57201 H. Totais | K10: 57203 H. Totais | L10: 57243 H. Totais | M10: 57264 H. Totais | N10: 57264 H. Totais | O10: 57265 H. Totais | P10: 57265 H. Totais | Q10: 37490 Arranque motor | R10: 57422 H. Totais | S10: 57423 H. Totais | T10: 57452 H. Totais | U10: 57452 H. Totais | V10: 57475 H. Totais | W10: 57647 H. Totais | X10: 57679 H. Totais | Y10: 57685 H. Totais | Z10: 57685 H. Totais | AA10: 57685 H. Totais | AB10: 57685 H. Totais | AC10: 57685 H. Totais | AD10: 57685 H. Totais | AE10: 57685 H. Totais | AF10: 57775 H. Totais | AG10: 57783 H. Totais | AH10: 57783 H. Totais | AI10: 57784 H. Totais | AJ10: 57792 H. Totais | AK10: 57792 H. Totais | AL10: 57792 H. Totais | AM10: 57875 H. Totais | AN10: 58142 H. Totais | AO10: 58240 H. Totais | AP10: 58361 H. Totais | AQ10: 58455 H. Totais | AR10: 58574 H. Totais | AS10: 58858 H. Totais | AT10: 59568 H. Totais | AU10: 59648 H. Totais | AV10: 59725 H. Totais | AW10: 59819 H. Totais | AX10: 59846 H. Totais | AY10: 59858 H. Totais | AZ10: 59895 H. Totais | BA10: 59905 H. Totais | BB10: 59945 H. Totais | BC10: 60012 H. Totais | BD10: 60320 H. Totais | BE10: 60414 H. Totais | BF10: 60683 H. Totais | BG10: 60683 H. Totais | BH10: 60683 H. Totais | BI10: 65535 H. Totais | BJ10: 65720 H. Totais | BK10: 65835 H. Totais | BL10: 65994 H. Totais
C11: 37441 Arranque motor | D11: 37442 Arranque motor | E11: 37446 Arranque motor | F11: 37449 Arranque motor | G11: 37452 Arranque motor | H11: 37453 Arranque motor | I11: 37453 Arranque motor | J11: 37464 Arranque moto | K11: 37465 Arranque motor | L11: 37468 Arranque motor | M11: 37470 Arranque motor | N11: 37470 Arranque motor | O11: 37481 Arranque motor | P11: 37481 Arranque motor | R11: 37494 Arranque motor | S11: 37495 Arranque motor | T11: 37498 Arranque motor | U11: 37499 Arranque motor | V11: 37502 Arranque motor | W11: 37504 Arranque motor | X11: 37508 Arranque motor | Y11: 37509 Arranque motor | Z11: 37510 Arranque motor | AA11: 37510 Arranque motor | AB11: 37510 Arranque motor | AC11: 37511 Arranque motor | AD11: 37512 Arranque motor | AE11: 37512 Arranque motor | AF11: 37549 Arranque motor | AG11: 37594 Arranque motor | AH11: 37603 Arranque motor | AI11: 37606 Arranque motor | AJ11: 37620 Arranque motor | AK11: 37620 Arranque motor | AL11: 37621 Arranque motor | AM11: 37625 Arranque motor | AN11: 37635 Arranque motor | AO11: 37638 Arranque motor | AP11: 37655 Arranque motor | AQ11: 37667 Arranque motor | AR11: 37673 Arranque motor | AS11: 37811 Arranque motor | AT11: 37991 Arranque motor | AU11: 37994 Arranque motor | AV11: 37999 Arranque motor | AW11: 38043 Arranque motor | AX11: 38047 Arranque motor | AY11: 38096 Arranque motor | AZ11: 38344 Arranque motor | BA11: 38946 Arranque motor | BB11: 39504 Arranque motor | BC11: 39641 Arranque motor | BD11: 39753 Arranque moto | BE11: 43427 Arranque motor | BF11: 43322 Arranque motor | BG11: 43322 Arranque motor | BH11: 43322 Arranque motor | BI11: 56035 Arranque motor | BJ11: 56037 Arranque motor | BK11: 56050 Arranque motor | BL11: 56055 Arranque motor
Q12: GA55ff Nº03
B13: GA55FF | C13: GA55ff Nº03 | D13: GA55ff Nº03 | E13: GA55ff Nº03 | F13: GA55ff Nº03 | G13: GA55ff Nº03 | H13: GA55ff Nº03 | I13: GA55ff Nº03 | J13: GA55ff Nº03 | K13: GA55ff Nº03 | L13: GA55ff Nº03 | M13: GA55ff Nº03 | N13: GA55ff Nº03 | O13: GA55ff Nº03 | P13: GA55ff Nº03 | Q13: 40544 H. Funcionamento | R13: GA55ff Nº03 | S13: GA55ff Nº03 | T13: GA55ff Nº03 | U13: GA55ff Nº03 | V13: GA55ff Nº03 | W13: GA55ff Nº03 | X13: GA55ff Nº03 | Y13: GA55ff Nº03 | Z13: GA55ff Nº03 | AA13: GA55ff Nº03 | AB13: GA55ff Nº03 | AC13: GA55ff Nº03 | AD13: GA55ff Nº03 | AE13: GA55ff Nº03 | AF13: GA55ff Nº03 | AG13: GA55ff Nº03 | AH13: GA55ff Nº03 | AI13: GA55ff Nº03 | AJ13: GA55ff Nº03 | AK13: GA55ff Nº03 | AL13: GA55ff Nº03 | AM13: GA55ff Nº03 | AN13: GA55ff Nº03 | AO13: GA55ff Nº03 | AP13: GA55ff Nº03 | AQ13: GA55ff Nº03 | AR13: GA55ff Nº03 | AS13: GA55ff Nº03 | AT13: GA55ff Nº03 | AU13: GA55ff Nº03 | AV13: GA55ff Nº03 | AW13: GA55ff Nº03 | AX13: GA55ff Nº03 | AY13: GA55ff Nº03 | AZ13: GA55ff Nº03 | BA13: GA55ff Nº03 | BB13: GA55ff Nº03 | BC13: GA55ff Nº03 | BD13: GA55ff Nº03 | BE13: GA55ff Nº03 | BF13: GA55ff Nº03 | BG13: GA55ff Nº03 | BH13: GA55ff Nº03 | BI13: GA55ff Nº03 | BJ13: GA55ff Nº03 | BK13: GA55ff Nº03 | BL13: GA55ff Nº03
C14: 40222 H. Funcionamento | D14: 40248 H. Funcionamento | E14: 40256 H. Funcionamento | F14: 40263 H. Funcionamento | G14: 40275 H. Funcionamento | H14: 40279 H. Funcionamento | I14: 40279 H. Funcionamento | J14: 40327 H. Funcionamento | K14: 40335 H. Funcionamento | L14: 40365 H. Funcionamento | M14: 40377 H. Funcionamento | N14: 40380 H. Funcionamento | O14: 40433 H. Funcionamento | P14: 40459 H. Funcionamento | Q14: 31923 H. Carga | R14: 40630 H. Funcionamento | S14: 40662 H. Funcionamento | T14: 40734 H. Funcionamento | U14: 40759 H. Funcionamento | V14: 40770 H. Funcionamento | W14: 40786 H. Funcionamento | X14: 40845 H. Funcionamento | Y14: 40928 H. Funcionamento | Z14: 41056 H. Funcionamento | AA14: 41092 H. Funcionamento | AB14: 41092 H. Funcionamento | AC14: 41100 H. Funcionamento | AD14: 41105 H. Funcionamento | AE14: 41110 H. Funcionamento | AF14: 41255 H. Funcionamento | AG14: 41309 H. Funcionamento | AH14: 41371 H. Funcionamento | AI14: 41433 H. Funcionamento | AJ14: 41534 H. Funcionamento | AK14: 41587 H. Funcionamento | AL14: 41404 H. Funcionamento | AM14: 41771 H. Funcionamento | AN14: 41840 H. Funcionamento | AO14: 41860 H. Funcionamento | AP14: 41970 H. Funcionamento | AQ14: 42082 H. Funcionamento | AR14: 42228 H. Funcionamento | AS14: 43084 H. Funcionamento | AT14: 43459 H. Funcionamento | AU14: 43475 H. Funcionamento | AV14: 43496 H. Funcionamento | AW14: 43535 H. Funcionamento | AX14: 43539 H. Funcionamento | AY14: 43541 H. Funcionamento | AZ14: 43547 H. Funcionamento | BA14: 43549 H. Funcionamento | BB14: 43571 H. Funcionamento | BC14: 43583 H. Funcionamento | BD14: 43618 H. Funcionamento | BE14: 43646 H. Funcionamento | BF14: 43738 H. Funcionamento | BG14: 43756 H. Funcionamento | BH14: 43756 H. Funcionamento | BI14: 45409 H. Funcionamento | BJ14: 45411H. Funcionamento | BK14: 45419 H. Funcionamento | BL14: 45434 H. Funcionamento
C15: 31751 H. Carga | D15: 31770 H. Carga | E15: 31773 H. Carga | F15: 31775 H. Carga | G15: 31779 H. Carga | H15: 31780 H. Carga | I15: 31780 H. Carga | J15: 31801 H. Carga | K15: 31803 H. Carga | L15: 31820 H. Carga | M15: 31824 H. Carga | N15: 31826 H. Carga | O15: 31857 H. Carga | P15: 31869 H. Carga | R15: 31950 H. Carga | S15: 31962 H. Carga | T15: 32017 H. Carga | U15: 32025 H. Carga | V15: 32024 H. Carga | W15: 32033 H. Carga | X15: 32054 H. Carga | Y15: 32084 H. Carga | Z15: 32123 H. Carga | AA15: 32134 H. Carga | AB15: 32135 H. Carga | AC15: 32139 H. Carga | AD15: 32143 H. Carga | AE15: 32147 H. Carga | AF15: 32193 H. Carga | AG15: 32208 H. Carga | AH15: 32232 H. Carga | AI15: 32254 H. Carga | AJ15: 32286 H. Carga | AK15: 32305 H. Carga | AL15: 32357 H. Carga | AM15: 32387 H. Carga | AN15: 32407 H. Carga | AO15: 32412 H. Carga | AP15: 32453 H. Carga | AQ15: 32484 H. Carga | AR15: 32541 H. Carga | AS15: 32869 H. Carga | AT15: 33115 H. Carga | AU15: 33127 H. Carga | AV15: 33147 H. Carga | AW15: 33167 H. Carga | AX15: 33170 H. Carga | AY15: 33171 H. Carga | AZ15: 33172 H. Carga | BA15: 33173 H. Carga | BB15: 33179 H. Carga | BC15: 33183 H. Carga | BD15: 33190 H. Carga | BE15: 33195 H. Carga | BF15: 33226 H. Carga | BG15: 33234 H. Carga | BH15: 33234 H. Carga | BI15: 34059 H. Carga | BJ15: 34060 H. Carga | BK15: 34063 H. Carga | BL15: 34068 H. Carga
Q16: GA45 Nº04
B17: GA45FF | C17: GA45 Nº04 | D17: GA45 Nº04 | E17: GA45 Nº04 | F17: GA45 Nº04 | G17: GA45 Nº04 | H17: GA45 Nº04 | I17: GA45 Nº04 | J17: GA45 Nº04 | K17: GA45 Nº04 | L17: GA45 Nº04 | M17: GA45 Nº04 | N17: GA45 Nº04 | O17: GA45 Nº04 | P17: GA45 Nº04 | Q17: 25393 H. Funcionamento | R17: GA45 Nº04 | S17: GA45 Nº04 | T17: GA45 Nº04 | U17: GA45 Nº04 | V17: GA45 Nº04 | W17: GA45 Nº04 | X17: GA45 Nº04 | Y17: GA45 Nº04 | Z17: GA45 Nº04 | AA17: GA45 Nº04 | AB17: GA45 Nº04 | AC17: GA45 Nº04 | AD17: GA45 Nº04 | AE17: GA45 Nº04 | AF17: GA45 Nº04 | AG17: GA45 Nº04 | AH17: GA45 Nº04 | AI17: GA45 Nº04 | AJ17: GA45 Nº04 | AK17: GA45 Nº04 | AL17: GA45 Nº04 | AM17: GA45 Nº04 | AN17: GA45 Nº04 | AO17: GA45 Nº04 | AP17: GA45 Nº04 | AQ17: GA45 Nº04 | AR17: GA45 Nº04 | AS17: GA45 Nº04 | AT17: GA45 Nº04 | AU17: GA45 Nº04 | AV17: GA45 Nº04 | AW17: GA45 Nº04 | AX17: GA45 Nº04 | AY17: GA45 Nº04 | AZ17: GA45 Nº04 | BA17: GA45 Nº04 | BB17: GA45 Nº04 | BC17: GA45 Nº04 | BD17: GA45 Nº04 | BE17: GA45 Nº04 | BF17: GA45 Nº04 | BG17: GA45 Nº04 | BH17: GA45 Nº04 | BI17: GA45 Nº04 | BJ17: GA45 Nº04 | BK17: GA45 Nº04 | BL17: GA45 Nº04
C18: 25313 H. Funcionamento | D18: 25315 H. Funcionamento | E18: 25318 H. Funcionamento | F18: 25320 H. Funcionamento | G18: 25321 H. Funcionamento | H18: 25337 H. Funcionamento | I18: 25337 H. Funcionamento | J18: 25354 H. Funcionamento | K18: 25366 H. Funcionamento | L18: 25384 H. Funcionamento | M18: 25384 H. Funcionamento | N18: 25384 H. Funcionamento | O18: 25385 H. Funcionamento | P18: 25385 H. Funcionamento | Q18: 18848 H. Carga | R18: 25432 H. Funcionamento | S18: 25432 H. Funcionamento | T18: 25438 H. Funcionamento | U18: 25438 H. Funcionamento | V18: 25438 H. Funcionamento | W18: 25438 H. Funcionamento | X18: 25453 H. Funcionamento | Y18: 25492 H. Funcionamento | Z18: 25605 H. Funcionamento | AA18: 25643 H. Funcionamento | AB18: 25701 H. Funcionamento | AC18: 25747 H. Funcionamento | AD18: 25766 H. Funcionamento | AE18: 25773 H. Funcionamento | AF18: 25866 H. Funcionamento | AG18: 25928 H. Funcionamento | AH18: 25972 H. Funcionamento | AI18: 26016 H. Funcionamento | AJ18: 26089 H. Funcionamento | AK18: 26099 H. Funcionamento | AL18: 26117 H. Funcionamento | AM18: 26170 H. Funcionamento | AN18: 26170 H. Funcionamento COMPRESSOR ESTA EM MANUTENÇÃO ELÉTRICA | AO18: 26170 H. Funcionamento COMPRESSOR ESTA EM MANUTENÇÃO ELÉTRICA | AP18: 26190 H. Funcionamento | AQ18: 26263 H. Funcionamento | AR18: 26364 H. Funcionamento | AS18: 27107 H. Funcionamento | AT18: 27411 H. Funcionamento | AU18: 27419 H. Funcionamento | AV18: COMPRESSOR COM PROBLEMAS ELÉTRICOS. | AW18: COMPRESSOR COM PROBLEMAS ELÉTRICOS. | AX18: COMPRESSOR COM PROBLEMAS ELÉTRICOS NA IHM. | AY18: COMPRESSOR COM PROBLEMAS ELÉTRICOS NA IHM. | AZ18: COMPRESSOR COM PROBLEMAS ELÉTRICOS NA IHM. | BA18: COMPRESSOR COM PROBLEMAS ELÉTRICOS NA IHM. | BB18: COMPRESSOR COM PROBLEMAS ELÉTRICOS NA IHM. | BC18: COMPRESSOR COM PROBLEMAS ELÉTRICOS NA IHM. | BD18: COMPRESSOR COM PROBLEMAS ELÉTRICOS NA IHM. | BE18: 1 H.Funcionamento | BF18: H.Funcionamento Compressor N°04 aguardando chegada de mangueira | BG18: 84 H.Funcionamento | BH18: 84 H.Funcionamento | BI18: 84 1594H.Funcionamento | BJ18: 29033H.Funcionamento | BK18: 30.665H.Funcionamento | BL18: 30.665H.Funcionamento
C19: 18788 H. Carga | D19: 18789 H. Carga | E19: 18792 H. Carga | F19: 18792 H. Carga | G19: 18793 H. Carga | H19: 18798 H. Carga | I19: 18798 H. Carga | J19: 18814 H. Carga | K19: 18826 H. Carga | L19: 18844 H. Carga | M19: 18844 H. Carga | N19: 18844 H. Carga | O19: 18845 H. Carga | P19: 18845 H. Carga | R19: 18878 H. Carga | S19: 18878 H. Carga | T19: 18879 H. Carga | U19: 18879 H. Carga | V19: 18879 H. Carga | W19: 18879 H. Carga | X19: 18881 H. Carga | Y19: 18887 H. Carga | Z19: 18902 H. Carga | AA19: 18909 H. Carga | AB19: 18942 H. Carga | AC19: 18974 H. Carga | AD19: 18985 H. Carga | AE19: 18989 H. Carga | AF19: 19003 H. Carga | AG19: 19013 H. Carga | AH19: 19022 H. Carga | AI19: 19026 H. Carga | AJ19: 19032 H. Carga | AK19: 19032 H. Carga | AL19: 19036 H. Carga | AM19: 19048 H. Carga | AN19: 19048 H. Carga | AO19: 19048 H. Carga | AP19: 19052 H. Carga | AQ19: 19066 H. Carga | AR19: 19099 H. Carga | AS19: 19278 H. Carga | AT19: 19397 H. Carga | AU19: 19403 H. Carga | BE19: 0 H. Carga | BF19: H. Carga | BG19: 24 H. Carga | BH19: 24 H. Carga | BI19: 19829 H. Carga | BJ19: 20257 H. Carga | BK19: 20688 H. Carga | BL19: 20688 H. Carga
Q20: GA55VDS N°05
B21: GA55VDS | C21: GA55VDS N°05 | D21: GA55VDS N°05 | E21: GA55VDS N°05 | F21: GA55VDS N°05 | G21: GA55VDS N°05 | H21: GA55VDS N°05 | I21: GA55VDS N°05 | J21: GA55VDS N°05 | K21: GA55VDS N°05 | L21: GA55VDS N°05 | M21: GA55VDS N°05 | N21: GA55VDS N°05 | O21: GA55VDS N°05 | P21: GA55VDS N°05 | Q21: 3611 H. funcionamento | R21: GA55VDS N°05 | S21: GA55VDS N°05 | T21: GA55VDS N°05 | U21: GA55VDS N°05 | V21: GA55VDS N°05 | W21: GA55VDS N°05 | X21: GA55VDS N°05 | Y21: GA55VDS N°05 | Z21: GA55VDS N°05 | AA21: GA55VDS N°05 | AB21: GA55VDS N°05 | AC21: GA55VDS N°05 | AD21: GA55VDS N°05 | AE21: GA55VDS N°05 | AF21: GA55VDS N°05 | AG21: GA55VDS N°05 | AH21: GA55VDS N°05 | AI21: GA55VDS N°05 | AJ21: GA55VDS N°05 | AK21: GA55VDS N°05 | AL21: GA55VDS N°05 | AM21: GA55VDS N°05 | AN21: GA55VDS N°05 | AO21: GA55VDS N°05 | AP21: GA55VDS N°05 | AQ21: GA55VDS N°05 | AR21: GA55VDS N°05 | AS21: GA55VDS N°05 | AT21: GA55VDS N°05 | AU21: GA55VDS N°05 | AV21: GA55VDS N°05 | AW21: GA55VDS N°05 | AX21: GA55VDS N°05 | AY21: GA55VDS N°05 | AZ21: GA55VDS N°05 | BA21: GA55VDS N°05 | BB21: GA55VDS N°05 | BC21: GA55VDS N°05 | BD21: GA55VDS N°05 | BE21: GA55VDS N°05 | BF21: GA55VDS N°05 | BG21: GA55VDS N°05 | BH21: GA55VDS N°05 | BI21: GA55VDS N°05 | BJ21: GA55VDS N°05 | BK21: GA55VDS N°05 | BL21: GA55VDS N°05
C22: 1256 H. funcionamento | D22: 1414 H. funcionamento | E22: 1530 H. funcionamento | F22: 1694 H. funcionamento | G22: 1863 H. funcionamento | H22: 1916 H. funcionamento | I22: 1916 H. funcionamento | J22: 2248 H. funcionamento | K22: 2363 H. funcionamento | L22: 2583 H. funcionamento | M22: 2684 H. funcionamento | N22: 2807 H. funcionamento | O22: 3045 H. funcionamento | P22: 3254 H. funcionamento | R22: 3911 H. funcionamento | S22: 4200 H. funcionamento | T22: 4484 H. funcionamento | U22: 4734 H. funcionamento | V22: 4871 H. funcionamento | W22: 5112 H. funcionamento | X22: 5277 H. funcionamento | Y22: 5443 H. funcionamento | Z22: 5757 H. funcionamento | AA22: 5901 H. funcionamento | AB22: 6235 H. funcionamento | AC22: 6375 H. funcionamento | AD22: 6700 H. funcionamento | AE22: 6863 H. funcionamento | AF22: 7458 H. funcionamento | AG22: 7625 H. funcionamento | AH22: 7789 H. funcionamento | AI22: 7929 H. funcionamento | AJ22: 8134 H. funcionamento | AK22: 8229 H. funcionamento | AL22: 8572 H. funcionamento | AM22: 8821 H. funcionamento | AN22: 9232 H. funcionamento | AO22: 9394 H. funcionamento | AP22: 10007 H. funcionamento | AQ22: 10437 H. funcionamento | AR22: 10880 H. funcionamento | AS22: 12676 H. funcionamento | AT22: 13890 H. funcionamento | AU22: 14078 H. funcionamento | AV22: 14156 H. funcionamento | AW22: 14456 H. funcionamento | AX22: 14790 H. funcionamento | AY22: 15167 H. funcionamento | AZ22: 15404 H. funcionamento | BA22: 15501 H. funcionamento | BB22: 15858 H. funcionamento | BC22: 16005 H. funcionamen | BD22: 16556 H. funcionamento | BE22: 17123 H. funcionamento | BF22: 18089 H. funcionamento | BG22: 18316 H. funcionamento | BH22: 18316 H. funcionamento | BI22: 26949 H. funcionamento | BJ22: 27134 H. funcionamento | BK22: 27134 H. funcionamento | BL22: 27134 H. funcionamento
Q23: GA55VDS N°06 | BQ23: 9 numero de partida | BR23: 16 numero de partida | BS23: 26 numero de partida | BU23: 45 número partida
B24: GA55VDS | C24: GA55VDS N°06 | D24: GA55VDS N°06 | E24: GA55VDS N°06 | F24: GA55VDS N°06 | G24: GA55VDS N°06 | H24: GA55VDS N°06 | I24: GA55VDS N°06 | J24: GA55VDS N°06 | K24: GA55VDS N°06 | L24: GA55VDS N°06 | M24: GA55VDS N°06 | N24: GA55VDS N°06 | O24: GA55VDS N°06 | P24: GA55VDS N°06 | Q24: 3621 H. funcionamento | R24: GA55VDS N°06 | S24: GA55VDS N°06 | T24: GA55VDS N°06 | U24: GA55VDS N°06 | V24: GA55VDS N°06 | W24: GA55VDS N°06 | X24: GA55VDS N°06 | Y24: GA55VDS N°06 | Z24: GA55VDS N°06 | AA24: GA55VDS N°06 | AB24: GA55VDS N°06 | AC24: GA55VDS N°06 | AD24: GA55VDS N°06 | AE24: GA55VDS N°06 | AF24: GA55VDS N°06 | AG24: GA55VDS N°06 | AH24: GA55VDS N°06 | AI24: GA55VDS N°06 | AJ24: GA55VDS N°06 | AK24: GA55VDS N°06 | AL24: GA55VDS N°06 | AM24: GA55VDS N°06 | AN24: GA55VDS N°06 | AO24: GA55VDS N°06 | AP24: GA55VDS N°06 | AQ24: GA55VDS N°06 | AR24: GA55VDS N°06 | AS24: GA55VDS N°06 | AT24: GA55VDS N°06 | AU24: GA55VDS N°06 | AV24: GA55VDS N°06 | AW24: GA55VDS N°06 | AX24: GA55VDS N°06 | AY24: GA55VDS N°06 | AZ24: GA55VDS N°06 | BA24: GA55VDS N°06 | BB24: GA55VDS N°06 | BC24: GA55VDS N°06 | BD24: GA55VDS N°06 | BE24: GA55VDS N°06 | BF24: GA55VDS N°06 | BG24: GA55VDS N°06 | BH24: GA55VDS N°06 | BI24: GA55VDS N°06 | BJ24: GA55VDS N°06 | BK24: GA55VDS N°06 | BL24: GA55VDS N°06 | BT24: GA55VDS N°06
C25: 1270 H. funcionamento | D25: 1419 H. funcionamento | E25: 1536 H. funcionamento | F25: 1698 H. funcionamento | G25: 1869 H. funcionamento | H25: 1922 H. funcionamento | I25: 1922 H. funcionamento | J25: 2255 H. funcionamento | K25: 2374 H. funcionamento | L25: 2557 H. funcionamento | M25: 2656 H. funcionamento | N25: 2787 H. funcionamento | O25: 3047 H. funcionamento | P25: 3263 H. funcionamento | R25: 3953 H. funcionamento | S25: 4241 H. funcionamento | T25: 4532 H. funcionamento | U25: 4782 H. funcionamento | V25: 4883 H. funcionamento | W25: 5121 H. funcionamento | X25: 5286 H. funcionamento | Y25: 5452 H. funcionamento | Z25: 5796 H. funcionamento | AA25: 5939 H. funcionamento | AB25: 6214 H. funcionamento | AC25: 6355 H. funcionamento | AD25: 6676 H. funcionamento | AE25: 6840 H. funcionamento | AF25: 7433 H. funcionamento | AG25: 7600 H. funcionamento | AH25: 7757 H. funcionamento | AI25: 7906 H. funcionamento | AJ25: 8111 H. funcionamento | AK25: 8205 H. funcionamento | AL25: 8609 H. funcionamento | AM25: 8853 H. funcionamento | AN25: 9301 H. funcionamento | AO25: 9469 H. funcionamento | AP25: 10070 H. funcionamento | AQ25: 10495 H. funcionamento | AR25: 10925 H. funcionamento | AS25: 12733 H. funcionamento | AT25: 13935 H. funcionamento | AU25: 14148 H. funcionamento | AV25: 14222 H. funcionamento | AW25: 14434 H. funcionamento | AX25: 14739 H. funcionamento | AY25: 15123 H. funcionamento | AZ25: 15363 H. funcionamento | BA25: 15452 H. funcionamento | BB25: 15847 H. funcionamento | BC25: 15983 H. funcionamento | BD25: 16516 H. funcionamento | BE25: 17097 H. funcionamento | BF25: 17999 H. funcionamento | BG25: 18222 H. funcionamento | BH25: 18222 H. funcionamento | BI25: 26463 H. funcionamento | BJ25: 26937 H. funcionamento | BK25: 27058 H. funcionamento | BL25: 27227 H. funcionamento | BQ25: ga55vds n°06 | BR25: ga55vds n°06 | BS25: ga55vds n°06 | BT25: 534 H. funcionamento | BU25: GA55VSDff n°06
BQ26: 117 h. funcionamento | BR26: 250 h. funcionamento | BS26: 389 h. funcionamento | BU26: 832 H.funcionamento
E27: Instalação dos filtros coalescentes em todos os compressores nesta data | I27: Essas horas dos compressores N°01,02 e 04 são da manutenção realizada no compressor pela a motriz, o mesmo não esta em funcionamento. | BQ27: 12 numero de partida | BR27: 19 numero de partida | BS27: 37 numero de partida | BU27: 59 númeropartida
